output/10.txt
time symbol vwap
10:00:00 A 73.12
10:00:00 AA 52.74
10:00:00 AAAP 82.11
10:00:00 AABA 78.38
10:00:00 AAL 52.66
10:00:00 AAN 42.02
10:00:00 AAOI 32.91
10:00:00 AAON 36.05
10:00:00 AAP 119.17
10:00:00 AAPL 166.8
10:00:00 AAT 34.85
10:00:00 AAU 0.87
10:00:00 AAV 3.32
10:00:00 AAWW 57.41
10:00:00 AAXJ 81.29
10:00:00 AAXN 27.5
10:00:00 AB 27.6
10:00:00 ABAC 2.84
10:00:00 ABAX 74.18
10:00:00 ABB 28.02
10:00:00 ABBV 116.27
10:00:00 ABC 102.7
10:00:00 ABCB 55.05
10:00:00 ABCD 7.14
10:00:00 ABDC 7.99
10:00:00 ABEO 15.34
10:00:00 ABEV 6.84
10:00:00 ABG 74.38
10:00:00 ABIL 0.47
10:00:00 ABIO 1.8
10:00:00 ABLX 54.06
10:00:00 ABM 38.37
10:00:00 ABMD 234.87
10:00:00 ABR 8.2
10:00:00 ABT 62.53
10:00:00 ABTX 40.63
10:00:00 ABX 14.32
10:00:00 ACAD 30.72
10:00:00 ACBI 17.7
10:00:00 ACC 38.26
10:00:00 ACCO 11.97
10:00:00 ACER 19.28
10:00:00 ACET 11.53
10:00:00 ACFC 10.53
10:00:00 ACGL 90.97
10:00:00 ACGLO 24.23
10:00:00 ACGLP 23.08
10:00:00 ACH 17.47
10:00:00 ACHC 34.3
10:00:00 ACHN 2.77
10:00:00 ACIA 35.64
10:00:00 ACIU 13.52
10:00:00 ACIW 23.07
10:00:00 ACLS 26.26
10:00:00 ACM 39.14
10:00:00 ACN 159.98
10:00:00 ACNB 30.29
10:00:00 ACOR 26.47
10:00:00 ACRS 22.55
10:00:00 ACSF 10.79
10:00:00 ACST 1.16
10:00:00 ACTA 15.54
10:00:00 ACTG 3.88
10:00:00 ACU 24.27
10:00:00 ACV 22.23
10:00:00 ACWI 76.22
10:00:00 ACWV 87.01
10:00:00 ACWX 52.73
10:00:00 ACXM 27.66
10:00:00 ADAP 8.83
10:00:00 ADBE 197.08
10:00:00 ADC 47.88
10:00:00 ADES 8.13
10:00:00 ADI 91.7
10:00:00 ADM 42.55
10:00:00 ADMA 3.81
10:00:00 ADMP 3.68
10:00:00 ADMS 39.33
10:00:00 ADNT 66.1
10:00:00 ADOM 1.64
10:00:00 ADP 120.89
10:00:00 ADRE 47.54
10:00:00 ADRO 6.73
10:00:00 ADS 255.34
10:00:00 ADSK 115.27
10:00:00 ADSW 24.26
10:00:00 ADT 12.29
10:00:00 ADTN 16.12
10:00:00 ADUS 36.0
10:00:00 ADVM 7.91
10:00:00 ADX 15.83
10:00:00 ADXS 3.04
10:00:00 AE 45.6
10:00:00 AED 25.56
10:00:00 AEE 56.2
10:00:00 AEG 6.87
10:00:00 AEGN 25.32
10:00:00 AEH 25.56
10:00:00 AEHR 2.66
10:00:00 AEIS 72.37
10:00:00 AEL 33.98
10:00:00 AEM 47.35
10:00:00 AEMD 1.58
10:00:00 AEO 18.37
10:00:00 AEP 68.61
10:00:00 AER 54.25
10:00:00 AERI 56.19
10:00:00 AES 11.63
10:00:00 AET 188.73
10:00:00 AEUA 36.77
10:00:00 AEZS 2.25
10:00:00 AFAM 58.44
10:00:00 AFB 12.93
10:00:00 AFG 113.39
10:00:00 AFI 15.87
10:00:00 AFL 88.71
10:00:00 AFMD 1.32
10:00:00 AFSI 12.99
10:00:00 AFSI-D 18.77
10:00:00 AFSI-E 19.31
10:00:00 AFSS 23.51
10:00:00 AFST 24.58
10:00:00 AFT 16.26
10:00:00 AG 6.05
10:00:00 AGCO 73.0
10:00:00 AGD 11.23
10:00:00 AGEN 3.64
10:00:00 AGFS 7.58
10:00:00 AGG 107.98
10:00:00 AGGE 19.22
10:00:00 AGGY 50.03
10:00:00 AGI 6.0
10:00:00 AGII 61.92
10:00:00 AGIIL 25.3
10:00:00 AGIO 80.74
10:00:00 AGLE 6.94
10:00:00 AGM 80.87
10:00:00 AGN 184.67
10:00:00 AGNC 19.09
10:00:00 AGNCN 25.28
10:00:00 AGO 35.93
10:00:00 AGQ 34.4
10:00:00 AGR 48.33
10:00:00 AGRO 9.73
10:00:00 AGRX 3.28
10:00:00 AGS 19.47
10:00:00 AGTC 5.13
10:00:00 AGX 44.13
10:00:00 AGYS 12.15
10:00:00 AGZD 48.25
10:00:00 AHGP 28.73
10:00:00 AHH 14.34
10:00:00 AHL 37.58
10:00:00 AHL-C 25.49
10:00:00 AHP 9.2
10:00:00 AHPA 9.94
10:00:00 AHT 6.44
10:00:00 AHT-F 23.55
10:00:00 AHT-G 23.48
10:00:00 AI 10.78
10:00:00 AIA 71.02
10:00:00 AIEQ 27.59
10:00:00 AIF 15.55
10:00:00 AIG 63.4
10:00:00 AIG+ 21.59
10:00:00 AIMC 52.86
10:00:00 AIMT 35.49
10:00:00 AIN 63.0
10:00:00 AINV 5.72
10:00:00 AIR 40.0
10:00:00 AIRG 10.2
10:00:00 AIT 74.54
10:00:00 AIV 41.03
10:00:00 AIZ 92.3
10:00:00 AJG 69.6
10:00:00 AJRD 28.08
10:00:00 AKAM 66.63
10:00:00 AKAO 12.33
10:00:00 AKBA 15.08
10:00:00 AKCA 23.59
10:00:00 AKER 0.25
10:00:00 AKG 0.93
10:00:00 AKO.B 28.93
10:00:00 AKR 24.45
10:00:00 AKRX 32.23
10:00:00 AKS 5.52
10:00:00 AKTS 5.78
10:00:00 AKTX 2.84
10:00:00 AL 48.88
10:00:00 ALB 111.53
10:00:00 ALBO 36.31
10:00:00 ALCO 26.95
10:00:00 ALDR 14.37
10:00:00 ALDW 16.8
10:00:00 ALDX 7.58
10:00:00 ALE 71.98
10:00:00 ALEX 26.98
10:00:00 ALG 117.48
10:00:00 ALGN 269.2
10:00:00 ALGT 159.41
10:00:00 ALK 64.25
10:00:00 ALKS 57.51
10:00:00 ALL 98.73
10:00:00 ALL-F 26.02
10:00:00 ALLE 85.58
10:00:00 ALLT 4.97
10:00:00 ALLY 30.89
10:00:00 ALLY-A 25.92
10:00:00 ALNY 131.36
10:00:00 ALOG 83.75
10:00:00 ALPN 11.12
10:00:00 ALQA 2.14
10:00:00 ALRM 37.57
10:00:00 ALRN 9.26
10:00:00 ALSK 2.2
10:00:00 ALSN 44.75
10:00:00 ALTR 25.74
10:00:00 ALV 149.29
10:00:00 ALX 362.7
10:00:00 ALXN 122.63
10:00:00 AM 31.01
10:00:00 AMAG 14.43
10:00:00 AMAT 53.48
10:00:00 AMBA 50.91
10:00:00 AMBC 16.32
10:00:00 AMBR 7.26
10:00:00 AMC 12.57
10:00:00 AMCN 1.19
10:00:00 AMCX 52.78
10:00:00 AMD 12.93
10:00:00 AME 76.72
10:00:00 AMED 54.08
10:00:00 AMEH 19.92
10:00:00 AMG 203.97
10:00:00 AMGN 191.49
10:00:00 AMGP 21.26
10:00:00 AMH 20.12
10:00:00 AMJ 29.31
10:00:00 AMKR 10.12
10:00:00 AMLP 11.47
10:00:00 AMN 53.32
10:00:00 AMOT 34.91
10:00:00 AMP 172.29
10:00:00 AMPE 2.9
10:00:00 AMPH 19.01
10:00:00 AMRB 15.11
10:00:00 AMRH 2.65
10:00:00 AMRK 13.55
10:00:00 AMRN 3.82
10:00:00 AMRS 5.04
10:00:00 AMSC 5.26
10:00:00 AMSF 61.16
10:00:00 AMT 145.4
10:00:00 AMT-B 128.34
10:00:00 AMTD 55.52
10:00:00 AMWD 135.62
10:00:00 AMX 18.6
10:00:00 AMZA 8.61
10:00:00 AMZN 1433.76
10:00:00 AN 61.19
10:00:00 ANAB 106.27
10:00:00 ANAT 126.99
10:00:00 ANCX 28.89
10:00:00 ANDE 34.47
10:00:00 ANDV 109.01
10:00:00 ANDX 51.71
10:00:00 ANET 275.05
10:00:00 ANF 21.31
10:00:00 ANGI 13.63
10:00:00 ANGL 30.17
10:00:00 ANGO 17.26
10:00:00 ANH 4.97
10:00:00 ANIK 68.23
10:00:00 ANIP 67.71
10:00:00 ANSS 161.91
10:00:00 ANTH 1.72
10:00:00 ANTM 243.7
10:00:00 ANW 4.69
10:00:00 ANY 2.34
10:00:00 AOA 56.08
10:00:00 AOBC 12.09
10:00:00 AOD 9.86
10:00:00 AOI 13.04
10:00:00 AOK 34.93
10:00:00 AON 141.94
10:00:00 AOS 66.56
10:00:00 AOSL 16.86
10:00:00 APA 44.77
10:00:00 APAM 39.62
10:00:00 APC 59.92
10:00:00 APD 168.49
10:00:00 APDN 1.52
10:00:00 APEI 25.36
10:00:00 APEN 6.14
10:00:00 APH 92.68
10:00:00 APHB 1.2
10:00:00 APLE 19.52
10:00:00 APLP 13.67
10:00:00 APLS 18.32
10:00:00 APO 35.55
10:00:00 APOG 46.5
10:00:00 APOP 8.45
10:00:00 APPF 42.64
10:00:00 APPN 30.32
10:00:00 APPS 2.04
10:00:00 APRI 2.4
10:00:00 APRN 3.06
10:00:00 APTI 25.22
10:00:00 APTO 3.04
10:00:00 APTS 16.81
10:00:00 APTV 94.72
10:00:00 APU 47.36
10:00:00 APVO 3.38
10:00:00 AQ 13.21
10:00:00 AQMS 1.87
10:00:00 AQN 10.78
10:00:00 AQUA 22.98
10:00:00 AQXP 13.01
10:00:00 AR 19.49
10:00:00 ARA 18.96
10:00:00 ARAY 5.84
10:00:00 ARC 2.42
10:00:00 ARCB 35.96
10:00:00 ARCC 16.16
10:00:00 ARCH 90.12
10:00:00 ARCO 9.98
10:00:00 ARCT 8.01
10:00:00 ARD 20.02
10:00:00 ARDM 1.5
10:00:00 ARDX 7.43
10:00:00 ARE 125.85
10:00:00 AREX 3.38
10:00:00 ARGS 2.3
10:00:00 ARGX 78.05
10:00:00 ARI 18.34
10:00:00 ARII 39.54
10:00:00 ARKG 28.54
10:00:00 ARKQ 36.04
10:00:00 ARKW 50.57
10:00:00 ARL 13.93
10:00:00 ARLP 20.45
10:00:00 ARLZ 1.73
10:00:00 ARMK 45.5
10:00:00 ARMO 29.96
10:00:00 ARNA 37.47
10:00:00 ARNC 29.94
10:00:00 AROC 9.63
10:00:00 ARQL 1.71
10:00:00 ARR 23.87
10:00:00 ARRS 25.26
10:00:00 ARRY 14.76
10:00:00 ARTNA 37.25
10:00:00 ARTX 3.62
10:00:00 ARW 82.47
10:00:00 ARWR 6.13
10:00:00 ASA 11.45
10:00:00 ASB 24.91
10:00:00 ASC 7.18
10:00:00 ASCMA 9.9
10:00:00 ASGN 68.93
10:00:00 ASH 72.7
10:00:00 ASHR 33.57
10:00:00 ASIX 40.35
10:00:00 ASMB 50.02
10:00:00 ASML 200.6
10:00:00 ASNA 2.17
10:00:00 ASND 51.6
10:00:00 ASNS 12.96
10:00:00 ASPS 30.29
10:00:00 ASR 194.2
10:00:00 ASRV 4.18
10:00:00 ASRVP 27.7
10:00:00 ASTC 3.25
10:00:00 ASTE 63.06
10:00:00 ASUR 15.01
10:00:00 ASX 7.17
10:00:00 ASYS 10.18
10:00:00 ATAX 6.12
10:00:00 ATEN 6.99
10:00:00 ATGE 45.88
10:00:00 ATH 50.47
10:00:00 ATHM 82.61
10:00:00 ATHN 127.63
10:00:00 ATHX 1.8
10:00:00 ATI 27.66
10:00:00 ATKR 23.94
10:00:00 ATLC 2.27
10:00:00 ATMP 21.83
10:00:00 ATNI 59.43
10:00:00 ATNM 0.71
10:00:00 ATNX 14.96
10:00:00 ATO 82.57
10:00:00 ATOM 4.8
10:00:00 ATOS 0.54
10:00:00 ATR 87.68
10:00:00 ATRA 40.12
10:00:00 ATRC 16.88
10:00:00 ATRI 572.88
10:00:00 ATRO 45.65
10:00:00 ATRS 2.26
10:00:00 ATSG 24.74
10:00:00 ATTO 9.52
10:00:00 ATU 25.13
10:00:00 ATUS 21.81
10:00:00 ATVI 71.47
10:00:00 ATXI 3.87
10:00:00 AU 11.11
10:00:00 AUO 4.82
10:00:00 AUPH 5.51
10:00:00 AUTO 8.33
10:00:00 AUY 3.41
